[2024-12-02T18:55:51.737+0000] {local_task_job_runner.py:123} INFO - ::group::Pre task execution logs
[2024-12-02T18:55:51.759+0000] {taskinstance.py:2613} INFO - Dependencies all met for dep_context=non-requeueable deps ti=<TaskInstance: weather_data_pipeline.load_weather_data manual__2024-12-02T18:55:06.997654+00:00 [queued]>
[2024-12-02T18:55:51.771+0000] {taskinstance.py:2613} INFO - Dependencies all met for dep_context=requeueable deps ti=<TaskInstance: weather_data_pipeline.load_weather_data manual__2024-12-02T18:55:06.997654+00:00 [queued]>
[2024-12-02T18:55:51.772+0000] {taskinstance.py:2866} INFO - Starting attempt 1 of 2
[2024-12-02T18:55:51.792+0000] {taskinstance.py:2889} INFO - Executing <Task(PythonOperator): load_weather_data> on 2024-12-02 18:55:06.997654+00:00
[2024-12-02T18:55:51.801+0000] {warnings.py:112} WARNING - /home/***/.local/lib/python3.12/site-packages/***/task/task_runner/standard_task_runner.py:70: DeprecationWarning: This process (pid=2200) is multi-threaded, use of fork() may lead to deadlocks in the child.
  pid = os.fork()

[2024-12-02T18:55:51.803+0000] {standard_task_runner.py:72} INFO - Started process 2202 to run task
[2024-12-02T18:55:51.804+0000] {standard_task_runner.py:104} INFO - Running: ['***', 'tasks', 'run', 'weather_data_pipeline', 'load_weather_data', 'manual__2024-12-02T18:55:06.997654+00:00', '--job-id', '101', '--raw', '--subdir', 'DAGS_FOLDER/weather_pipeline.py', '--cfg-path', '/tmp/tmpatqp523l']
[2024-12-02T18:55:51.806+0000] {standard_task_runner.py:105} INFO - Job 101: Subtask load_weather_data
[2024-12-02T18:55:51.870+0000] {task_command.py:467} INFO - Running <TaskInstance: weather_data_pipeline.load_weather_data manual__2024-12-02T18:55:06.997654+00:00 [running]> on host 1a5e4afa404c
[2024-12-02T18:55:52.002+0000] {taskinstance.py:3132} INFO - Exporting env vars: AIRFLOW_CTX_DAG_EMAIL='andrew.marfo@amalitech.com' AIRFLOW_CTX_DAG_OWNER='***' AIRFLOW_CTX_DAG_ID='weather_data_pipeline' AIRFLOW_CTX_TASK_ID='load_weather_data' AIRFLOW_CTX_EXECUTION_DATE='2024-12-02T18:55:06.997654+00:00' AIRFLOW_CTX_TRY_NUMBER='1' AIRFLOW_CTX_DAG_RUN_ID='manual__2024-12-02T18:55:06.997654+00:00'
[2024-12-02T18:55:52.004+0000] {logging_mixin.py:190} INFO - Task instance is in running state
[2024-12-02T18:55:52.005+0000] {logging_mixin.py:190} INFO -  Previous state of the Task instance: queued
[2024-12-02T18:55:52.006+0000] {logging_mixin.py:190} INFO - Current task name:load_weather_data state:running start_date:2024-12-02 18:55:51.760654+00:00
[2024-12-02T18:55:52.006+0000] {logging_mixin.py:190} INFO - Dag name:weather_data_pipeline and current dag run status:running
[2024-12-02T18:55:52.007+0000] {taskinstance.py:731} INFO - ::endgroup::
[2024-12-02T18:55:52.033+0000] {base.py:84} INFO - Retrieving connection 'weather_data'
[2024-12-02T18:55:52.113+0000] {taskinstance.py:3311} ERROR - Task failed with exception
Traceback (most recent call last):
  File "/home/airflow/.local/lib/python3.12/site-packages/airflow/models/taskinstance.py", line 767, in _execute_task
    result = _execute_callable(context=context, **execute_callable_kwargs)
             ^^^^^^^^^^^^^^^^^^^^^^^^^^^^^^^^^^^^^^^^^^^^^^^^^^^^^^^^^^^^^
  File "/home/airflow/.local/lib/python3.12/site-packages/airflow/models/taskinstance.py", line 733, in _execute_callable
    return ExecutionCallableRunner(
           ^^^^^^^^^^^^^^^^^^^^^^^^
  File "/home/airflow/.local/lib/python3.12/site-packages/airflow/utils/operator_helpers.py", line 252, in run
    return self.func(*args, **kwargs)
           ^^^^^^^^^^^^^^^^^^^^^^^^^^
  File "/home/airflow/.local/lib/python3.12/site-packages/airflow/models/baseoperator.py", line 417, in wrapper
    return func(self, *args, **kwargs)
           ^^^^^^^^^^^^^^^^^^^^^^^^^^^
  File "/home/airflow/.local/lib/python3.12/site-packages/airflow/operators/python.py", line 238, in execute
    return_value = self.execute_callable()
                   ^^^^^^^^^^^^^^^^^^^^^^^
  File "/home/airflow/.local/lib/python3.12/site-packages/airflow/operators/python.py", line 256, in execute_callable
    return runner.run(*self.op_args, **self.op_kwargs)
           ^^^^^^^^^^^^^^^^^^^^^^^^^^^^^^^^^^^^^^^^^^^
  File "/home/airflow/.local/lib/python3.12/site-packages/airflow/utils/operator_helpers.py", line 252, in run
    return self.func(*args, **kwargs)
           ^^^^^^^^^^^^^^^^^^^^^^^^^^
  File "/opt/airflow/dags/weather_pipeline.py", line 135, in load_to_postgres
    cursor.execute(insert_query,(
psycopg2.errors.UndefinedTable: relation "weather_data.daily_weather" does not exist
LINE 2:         INSERT INTO  weather_data.daily_weather (id, city, t...
                             ^

[2024-12-02T18:55:52.133+0000] {logging_mixin.py:190} INFO - Task instance in failure state
[2024-12-02T18:55:52.134+0000] {logging_mixin.py:190} INFO - Task start:2024-12-02 18:55:51.760654+00:00 end:2024-12-02 18:55:52.132703+00:00 duration:0.372049
[2024-12-02T18:55:52.134+0000] {logging_mixin.py:190} INFO - Task:<Task(PythonOperator): load_weather_data> dag:<DAG: weather_data_pipeline> dagrun:<DagRun weather_data_pipeline @ 2024-12-02 18:55:06.997654+00:00: manual__2024-12-02T18:55:06.997654+00:00, state:running, queued_at: 2024-12-02 18:55:07.007626+00:00. externally triggered: True>
[2024-12-02T18:55:52.135+0000] {logging_mixin.py:190} INFO - Failure caused by relation "weather_data.daily_weather" does not exist
LINE 2:         INSERT INTO  weather_data.daily_weather (id, city, t...
                             ^
[2024-12-02T18:55:52.135+0000] {taskinstance.py:1225} INFO - Marking task as UP_FOR_RETRY. dag_id=weather_data_pipeline, task_id=load_weather_data, run_id=manual__2024-12-02T18:55:06.997654+00:00, execution_date=20241202T185506, start_date=20241202T185551, end_date=20241202T185552
[2024-12-02T18:55:52.159+0000] {taskinstance.py:340} INFO - ::group::Post task execution logs
[2024-12-02T18:55:52.160+0000] {standard_task_runner.py:124} ERROR - Failed to execute job 101 for task load_weather_data (relation "weather_data.daily_weather" does not exist
LINE 2:         INSERT INTO  weather_data.daily_weather (id, city, t...
                             ^
; 2202)
Traceback (most recent call last):
  File "/home/airflow/.local/lib/python3.12/site-packages/airflow/task/task_runner/standard_task_runner.py", line 117, in _start_by_fork
    ret = args.func(args, dag=self.dag)
          ^^^^^^^^^^^^^^^^^^^^^^^^^^^^^
  File "/home/airflow/.local/lib/python3.12/site-packages/airflow/cli/cli_config.py", line 49, in command
    return func(*args, **kwargs)
           ^^^^^^^^^^^^^^^^^^^^^
  File "/home/airflow/.local/lib/python3.12/site-packages/airflow/utils/cli.py", line 116, in wrapper
    return f(*args, **kwargs)
           ^^^^^^^^^^^^^^^^^^
  File "/home/airflow/.local/lib/python3.12/site-packages/airflow/cli/commands/task_command.py", line 483, in task_run
    task_return_code = _run_task_by_selected_method(args, _dag, ti)
                       ^^^^^^^^^^^^^^^^^^^^^^^^^^^^^^^^^^^^^^^^^^^^
  File "/home/airflow/.local/lib/python3.12/site-packages/airflow/cli/commands/task_command.py", line 256, in _run_task_by_selected_method
    return _run_raw_task(args, ti)
           ^^^^^^^^^^^^^^^^^^^^^^^
  File "/home/airflow/.local/lib/python3.12/site-packages/airflow/cli/commands/task_command.py", line 341, in _run_raw_task
    return ti._run_raw_task(
           ^^^^^^^^^^^^^^^^^
  File "/home/airflow/.local/lib/python3.12/site-packages/airflow/utils/session.py", line 97, in wrapper
    return func(*args, session=session, **kwargs)
           ^^^^^^^^^^^^^^^^^^^^^^^^^^^^^^^^^^^^^^
  File "/home/airflow/.local/lib/python3.12/site-packages/airflow/models/taskinstance.py", line 3005, in _run_raw_task
    return _run_raw_task(
           ^^^^^^^^^^^^^^
  File "/home/airflow/.local/lib/python3.12/site-packages/airflow/models/taskinstance.py", line 273, in _run_raw_task
    TaskInstance._execute_task_with_callbacks(
  File "/home/airflow/.local/lib/python3.12/site-packages/airflow/models/taskinstance.py", line 3159, in _execute_task_with_callbacks
    result = self._execute_task(context, task_orig)
             ^^^^^^^^^^^^^^^^^^^^^^^^^^^^^^^^^^^^^^
  File "/home/airflow/.local/lib/python3.12/site-packages/airflow/models/taskinstance.py", line 3183, in _execute_task
    return _execute_task(self, context, task_orig)
           ^^^^^^^^^^^^^^^^^^^^^^^^^^^^^^^^^^^^^^^
  File "/home/airflow/.local/lib/python3.12/site-packages/airflow/models/taskinstance.py", line 767, in _execute_task
    result = _execute_callable(context=context, **execute_callable_kwargs)
             ^^^^^^^^^^^^^^^^^^^^^^^^^^^^^^^^^^^^^^^^^^^^^^^^^^^^^^^^^^^^^
  File "/home/airflow/.local/lib/python3.12/site-packages/airflow/models/taskinstance.py", line 733, in _execute_callable
    return ExecutionCallableRunner(
           ^^^^^^^^^^^^^^^^^^^^^^^^
  File "/home/airflow/.local/lib/python3.12/site-packages/airflow/utils/operator_helpers.py", line 252, in run
    return self.func(*args, **kwargs)
           ^^^^^^^^^^^^^^^^^^^^^^^^^^
  File "/home/airflow/.local/lib/python3.12/site-packages/airflow/models/baseoperator.py", line 417, in wrapper
    return func(self, *args, **kwargs)
           ^^^^^^^^^^^^^^^^^^^^^^^^^^^
  File "/home/airflow/.local/lib/python3.12/site-packages/airflow/operators/python.py", line 238, in execute
    return_value = self.execute_callable()
                   ^^^^^^^^^^^^^^^^^^^^^^^
  File "/home/airflow/.local/lib/python3.12/site-packages/airflow/operators/python.py", line 256, in execute_callable
    return runner.run(*self.op_args, **self.op_kwargs)
           ^^^^^^^^^^^^^^^^^^^^^^^^^^^^^^^^^^^^^^^^^^^
  File "/home/airflow/.local/lib/python3.12/site-packages/airflow/utils/operator_helpers.py", line 252, in run
    return self.func(*args, **kwargs)
           ^^^^^^^^^^^^^^^^^^^^^^^^^^
  File "/opt/airflow/dags/weather_pipeline.py", line 135, in load_to_postgres
    cursor.execute(insert_query,(
psycopg2.errors.UndefinedTable: relation "weather_data.daily_weather" does not exist
LINE 2:         INSERT INTO  weather_data.daily_weather (id, city, t...
                             ^

[2024-12-02T18:55:52.220+0000] {local_task_job_runner.py:266} INFO - Task exited with return code 1
[2024-12-02T18:55:52.250+0000] {taskinstance.py:3895} INFO - 0 downstream tasks scheduled from follow-on schedule check
[2024-12-02T18:55:52.255+0000] {local_task_job_runner.py:245} INFO - ::endgroup::
